Workbook

Sheet Activities
A1: CTE – Linked Learning · Activities
A2: Edit this tab to update the Gantt automatically. Fill in Start/End for continuous activities, OR Custom months (e.g. "8,10,1,3") for irregular ones.
A4: Workstream | B4: Activity | C4: Start month | D4: End month | E4: Custom months | F4: Effort (1–4) | G4: Milestone? | H4: Who | I4: Notes | J4: Link
A5: CTE Pathway, Scheduling & Funding | B5: CTE master scheduling, pathway completion & Elevate error review | E5: 1,2,3,4,5,6,7,9,12 | F5: 1 | G5: No | H5: Coaches | I5: Consolidates recurring master-schedule planning, concentrator/capstone checks, and administrator/counselor follow-up.
A6: CTE Pathway, Scheduling & Funding | B6: Unified Funding Application cycle: orientation, troubleshooting, application & purchasing support | E6: 2,3,4,7,8,9,12 | F6: 2 | G6: No | H6: Coaches | I6: Combines application-window support, deadline follow-up, budget alignment, and award purchasing support.
A7: CTE Pathway, Scheduling & Funding | B7: GSPP planning, implementation & spending support | E7: 3,5,6,7,8,9,11,12 | F7: 2 | G7: No | H7: Coaches | I7: Includes PD, implementation coaching, goal progress, and spending support.
A8: CTE Pathway, Scheduling & Funding | B8: Course equivalencies development | C8: 2 | D8: 5 | F8: 2 | G8: No | H8: Coaches | I8: Equitably assigned course-equivalency work.
A9: Instructional Design, PBL & Defenses | B9: PBL/HQIM annual planning, pilot reflection & improvement design | E9: 11,12 | F9: 1 | G9: No | H9: Coaches | I9: Consolidates pilot reflection, theory of action, and annual instructional planning.
A10: Instructional Design, PBL & Defenses | B10: PBL/HQIM school-site coaching and professional learning | C10: 3 | D10: 9 | F10: 3 | G10: No | H10: Coaches | I10: Core instructional coaching and PD at school sites.
A11: Instructional Design, PBL & Defenses | B11: Linked Learning onboarding / August PBL professional learning | C11: 2 | D11: 2 | F11: 2 | G11: Yes | H11: Coaches | I11: Major August onboarding/PBL event; shown on Gantt but excluded from capacity totals as a milestone.
A12: Instructional Design, PBL & Defenses | B12: PBL 101 / fall instructional training | C12: 4 | D12: 4 | F12: 3 | G12: No | H12: Coaches | I12: October PBL 101 and related fall instructional training.
A13: Instructional Design, PBL & Defenses | B13: Defense calibration, support, feedback & reflection | E13: 7,8,9,11 | F13: 2 | G13: No | H13: Coaches | I13: Combines calibration, school support, feedback, and review of defense quality/data.
A14: Pathway Strategy, Data & Certification | B14: Administrator goal-setting, priorities & annual data review | E14: 1,2,12 | F14: 2 | G14: No | H14: Both | I14: Annual planning and data review with administrators; includes follow-up review of school goals.
A15: Pathway Strategy, Data & Certification | B15: School goal progress checks and targeted support planning | E15: 4,5,11 | F15: 2 | G15: No | H15: Both | I15: Team reviews progress, identifies patterns, and plans differentiated support.
A16: Pathway Strategy, Data & Certification | B16: Linked Learning certification planning & school support | C16: 2 | D16: 10 | F16: 2 | G16: No | H16: Both | I16: Support for schools pursuing Silver, Gold, or other Linked Learning certification milestones.
A17: Pathway Strategy, Data & Certification | B17: Team data checks, accomplishments review & next-year goal setting | E17: 3,7,11,12 | F17: 1 | G17: No | H17: Both | I17: Includes CTE completion, WBL, MiSiS tagging, CCR/dashboard outcomes, and year-end reflection.
A18: Pathway Strategy, Data & Certification | B18: Cross-team funding review & GSPP 3-year planning | E18: 9,12 | F18: 1 | G18: No | H18: Both | I18: Funding application scoring and cross-team GSPP planning.
A19: Professional Learning & Leadership | B19: Linked Learning Team retreat | C19: 1 | D19: 1 | F19: 1 | G19: Yes | H19: Both | I19: Team retreat / annual launch; milestone excluded from load totals.
A20: Professional Learning & Leadership | B20: Linked Learning Leaders professional learning series | E20: 3,4,7,8,10 | F20: 2 | G20: No | H20: Coaches | I20: Planning and facilitation of Leaders PD/workshops across the year.
A21: Professional Learning & Leadership | B21: Linked Learning microcredential program | C21: 1 | D21: 11 | F21: 1 | G21: No | H21: Coaches | I21: Promotion, facilitation, support-provider coordination, and participant support across the annual cycle.
A22: Professional Learning & Leadership | B22: Administrator Linked Learning information sessions | C22: 1 | D22: 3 | F22: 2 | G22: No | H22: Coaches | I22: July–September information sessions for school administrators.
A23: Professional Learning & Leadership | B23: LL Conference, Showcase & recognition activities | E23: 4,9,10 | F23: 2 | G23: No | H23: Both | I23: Includes conference, CTE-Linked Learning Showcase, and leader/student recognition work.
A24: Professional Learning & Leadership | B24: Department planning, team committees & cross-functional coordination | C24: 2 | D24: 9 | F24: 1 | G24: No | H24: Both | I24: Recurring department planning and internal committee work.
A25: Professional Learning & Leadership | B25: School Redesign Grant demonstration site visits | E25: 3,5,9 | F25: 2 | G25: Yes | H25: Coaches | I25: Demonstration site visits for Linked Learning Leads; milestone dates shown but excluded from capacity totals.
A26: WBL Planning, Partnerships & Career Exposure | B26: Annual WBL plan, priorities, checkpoints & year-end reflection | E26: 1,3,7,9,11,12 | F26: 2 | G26: No | H26: Coordinators | I26: Combines annual planning, school checkpoints, next-year visioning, and reflection.
A27: WBL Planning, Partnerships & Career Exposure | B27: Employer/community partner outreach & industry partnership development | C27: 2 | D27: 12 | F27: 2 | G27: No | H27: Coordinators | I27: Ongoing employer outreach, onboarding, relationship development, and industry mapping.
A28: WBL Planning, Partnerships & Career Exposure | B28: Career Days, college/career fairs & pathway event planning/support | C28: 3 | D28: 11 | F28: 3 | G28: No | H28: Coordinators | I28: Major event-planning responsibility including industry partner recruitment and school support.
A29: WBL Planning, Partnerships & Career Exposure | B29: WBL connections for PBL and classroom learning | C29: 3 | D29: 11 | F29: 2 | G29: No | H29: Coordinators | I29: Industry speakers, partners, and career-connected experiences that support PBL units.
A30: Internships & Work Readiness | B30: School-site work readiness implementation support | C30: 1 | D30: 12 | F30: 2 | G30: No | H30: Coordinators | I30: Ongoing support for school implementation of work-readiness systems and student preparation.
A31: Internships & Work Readiness | B31: Work readiness PD, workshops & orientations | E31: 3,4,5 | F31: 2 | G31: No | H31: Coordinators | I31: Staff/student-facing work readiness training, career-readiness workshops, and orientations.
A32: Internships & Work Readiness | B32: Student outreach, recruitment, applications, matching & placement | C32: 3 | D32: 9 | F32: 3 | G32: No | H32: Coordinators | I32: Consolidates student marketing/recruitment, applications, matching, interviews, and placement.
A33: Internships & Work Readiness | B33: Intern and worksite supervisor training/onboarding | C33: 3 | D33: 10 | F33: 2 | G33: No | H33: Coordinators | I33: Pre-placement and ongoing training for interns and worksite supervisors.
A34: Internships & Work Readiness | B34: Internship administration: timesheets, check-ins & ongoing support | C34: 3 | D34: 12 | F34: 3 | G34: No | H34: Coordinators | I34: Recurring timesheet processing and intern/worksite supervisor check-ins throughout placements.
A35: Internships & Work Readiness | B35: Teacher-led internship program support | C35: 3 | D35: 12 | F35: 1 | G35: No | H35: Coordinators | I35: Support for school-based/teacher-led internship programs beyond centrally managed placements.
A36: Internships & Work Readiness | B36: Internship closeout & program reflection | C36: 11 | D36: 12 | F36: 2 | G36: No | H36: Coordinators | I36: End-of-program closeout meetings and reflection with students/employers.
A37: Internships & Work Readiness | B37: Parent/student information & campus outreach | C37: 2 | D37: 5 | F37: 1 | G37: No | H37: Coordinators | I37: Information sessions, student/campus marketing, expectations, and communications.
A38: Internships & Work Readiness | B38: IRC / Workplace Readiness Badge implementation | C38: 5 | D38: 5 | F38: 2 | G38: No | H38: Coordinators | I38: Support for industry-recognized and workplace-readiness credentials tied to internship readiness.
A39: WBL Operations, Logistics & Reporting | B39: Field trip coordination, transportation & documentation logistics | C39: 2 | D39: 11 | F39: 2 | G39: No | H39: Coordinators | I39: Bus requests, approvals, documentation, follow-up, and trip logistics.
A40: WBL Operations, Logistics & Reporting | B40: Purchasing & procurement support | C40: 1 | D40: 12 | F40: 2 | G40: No | H40: Coordinators | I40: Quotes, purchase requests, purchase-order follow-up, and procurement troubleshooting.
A41: WBL Operations, Logistics & Reporting | B41: MiSiS/WBL data systems, reporting, compliance & training | C41: 1 | D41: 12 | F41: 2 | G41: No | H41: Coordinators | I41: MiSiS/WBL systems, rosters, reporting, compliance documentation, and scheduled trainings.
...

Sheet Gantt
A1: CTE – Linked Learning · Team Capacity Gantt
A2: 2026–27 school year · Auto-rendered from the Activities tab. Edit there to update this view.
A4: Workstream | B4: Activity | C4: Jul | D4: Aug | E4: Sep | F4: Oct | G4: Nov | H4: Dec | I4: Jan | J4: Feb | K4: Mar | L4: Apr | M4: May | N4: Jun
A5: =IF(Activities!$A5<>"",Activities!$A5,"") -> CTE Pathway, Scheduling & Funding | B5: =IF(Activities!$B5<>"",Activities!$B5,"") -> CTE master scheduling, pathway completion & Elevate error review | C5: =IF(AND(Activities!$A5<>"",IF(Activities!$E5<>"",ISNUMBER(SEARCH(",1,",","&Activities!$E5&",")),AND(Activities!$C5<=1,Activities!$D5>=1))),IF(Activities!$H5="Coaches","🌱 ",IF(Activities!$H5="Coordinators","⚙️ ",IF(Activities!$H5="Both","👥 ","")))&Activities!$B5&CHAR(10)&REPT("●",Activities!$F5),"") -> 🌱 CTE master scheduling, pathway completion & Elevate error review ● | D5: =IF(AND(Activities!$A5<>"",IF(Activities!$E5<>"",ISNUMBER(SEARCH(",2,",","&Activities!$E5&",")),AND(Activities!$C5<=2,Activities!$D5>=2))),IF(Activities!$H5="Coaches","🌱 ",IF(Activities!$H5="Coordinators","⚙️ ",IF(Activities!$H5="Both","👥 ","")))&Activities!$B5&CHAR(10)&REPT("●",Activities!$F5),"") -> 🌱 CTE master scheduling, pathway completion & Elevate error review ● | E5: =IF(AND(Activities!$A5<>"",IF(Activities!$E5<>"",ISNUMBER(SEARCH(",3,",","&Activities!$E5&",")),AND(Activities!$C5<=3,Activities!$D5>=3))),IF(Activities!$H5="Coaches","🌱 ",IF(Activities!$H5="Coordinators","⚙️ ",IF(Activities!$H5="Both","👥 ","")))&Activities!$B5&CHAR(10)&REPT("●",Activities!$F5),"") -> 🌱 CTE master scheduling, pathway completion & Elevate error review ● | F5: =IF(AND(Activities!$A5<>"",IF(Activities!$E5<>"",ISNUMBER(SEARCH(",4,",","&Activities!$E5&",")),AND(Activities!$C5<=4,Activities!$D5>=4))),IF(Activities!$H5="Coaches","🌱 ",IF(Activities!$H5="Coordinators","⚙️ ",IF(Activities!$H5="Both","👥 ","")))&Activities!$B5&CHAR(10)&REPT("●",Activities!$F5),"") -> 🌱 CTE master scheduling, pathway completion & Elevate error review ● | G5: =IF(AND(Activities!$A5<>"",IF(Activities!$E5<>"",ISNUMBER(SEARCH(",5,",","&Activities!$E5&",")),AND(Activities!$C5<=5,Activities!$D5>=5))),IF(Activities!$H5="Coaches","🌱 ",IF(Activities!$H5="Coordinators","⚙️ ",IF(Activities!$H5="Both","👥 ","")))&Activities!$B5&CHAR(10)&REPT("●",Activities!$F5),"") -> 🌱 CTE master scheduling, pathway completion & Elevate error review ● | H5: =IF(AND(Activities!$A5<>"",IF(Activities!$E5<>"",ISNUMBER(SEARCH(",6,",","&Activities!$E5&",")),AND(Activities!$C5<=6,Activities!$D5>=6))),IF(Activities!$H5="Coaches","🌱 ",IF(Activities!$H5="Coordinators","⚙️ ",IF(Activities!$H5="Both","👥 ","")))&Activities!$B5&CHAR(10)&REPT("●",Activities!$F5),"") -> 🌱 CTE master scheduling, pathway completion & Elevate error review ● | I5: =IF(AND(Activities!$A5<>"",IF(Activities!$E5<>"",ISNUMBER(SEARCH(",7,",","&Activities!$E5&",")),AND(Activities!$C5<=7,Activities!$D5>=7))),IF(Activities!$H5="Coaches","🌱 ",IF(Activities!$H5="Coordinators","⚙️ ",IF(Activities!$H5="Both","👥 ","")))&Activities!$B5&CHAR(10)&REPT("●",Activities!$F5),"") -> 🌱 CTE master scheduling, pathway completion & Elevate error review ● | J5: =IF(AND(Activities!$A5<>"",IF(Activities!$E5<>"",ISNUMBER(SEARCH(",8,",","&Activities!$E5&",")),AND(Activities!$C5<=8,Activities!$D5>=8))),IF(Activities!$H5="Coaches","🌱 ",IF(Activities!$H5="Coordinators","⚙️ ",IF(Activities!$H5="Both","👥 ","")))&Activities!$B5&CHAR(10)&REPT("●",Activities!$F5),"") | K5: =IF(AND(Activities!$A5<>"",IF(Activities!$E5<>"",ISNUMBER(SEARCH(",9,",","&Activities!$E5&",")),AND(Activities!$C5<=9,Activities!$D5>=9))),IF(Activities!$H5="Coaches","🌱 ",IF(Activities!$H5="Coordinators","⚙️ ",IF(Activities!$H5="Both","👥 ","")))&Activities!$B5&CHAR(10)&REPT("●",Activities!$F5),"") -> 🌱 CTE master scheduling, pathway completion & Elevate error review ● | L5: =IF(AND(Activities!$A5<>"",IF(Activities!$E5<>"",ISNUMBER(SEARCH(",10,",","&Activities!$E5&",")),AND(Activities!$C5<=10,Activities!$D5>=10))),IF(Activities!$H5="Coaches","🌱 ",IF(Activities!$H5="Coordinators","⚙️ ",IF(Activities!$H5="Both","👥 ","")))&Activities!$B5&CHAR(10)&REPT("●",Activities!$F5),"") | M5: =IF(AND(Activities!$A5<>"",IF(Activities!$E5<>"",ISNUMBER(SEARCH(",11,",","&Activities!$E5&",")),AND(Activities!$C5<=11,Activities!$D5>=11))),IF(Activities!$H5="Coaches","🌱 ",IF(Activities!$H5="Coordinators","⚙️ ",IF(Activities!$H5="Both","👥 ","")))&Activities!$B5&CHAR(10)&REPT("●",Activities!$F5),"") | N5: =IF(AND(Activities!$A5<>"",IF(Activities!$E5<>"",ISNUMBER(SEARCH(",12,",","&Activities!$E5&",")),AND(Activities!$C5<=12,Activities!$D5>=12))),IF(Activities!$H5="Coaches","🌱 ",IF(Activities!$H5="Coordinators","⚙️ ",IF(Activities!$H5="Both","👥 ","")))&Activities!$B5&CHAR(10)&REPT("●",Activities!$F5),"") -> 🌱 CTE master scheduling, pathway completion & Elevate error review ●
A6: =IF(Activities!$A6<>"",Activities!$A6,"") -> CTE Pathway, Scheduling & Funding | B6: =IF(Activities!$B6<>"",Activities!$B6,"") -> Unified Funding Application cycle: orientation, troubleshooting, application & purchasing support | C6: =IF(AND(Activities!$A6<>"",IF(Activities!$E6<>"",ISNUMBER(SEARCH(",1,",","&Activities!$E6&",")),AND(Activities!$C6<=1,Activities!$D6>=1))),IF(Activities!$H6="Coaches","🌱 ",IF(Activities!$H6="Coordinators","⚙️ ",IF(Activities!$H6="Both","👥 ","")))&Activities!$B6&CHAR(10)&REPT("●",Activities!$F6),"") | D6: =IF(AND(Activities!$A6<>"",IF(Activities!$E6<>"",ISNUMBER(SEARCH(",2,",","&Activities!$E6&",")),AND(Activities!$C6<=2,Activities!$D6>=2))),IF(Activities!$H6="Coaches","🌱 ",IF(Activities!$H6="Coordinators","⚙️ ",IF(Activities!$H6="Both","👥 ","")))&Activities!$B6&CHAR(10)&REPT("●",Activities!$F6),"") -> 🌱 Unified Funding Application cycle: orientation, troubleshooting, application & purchasing support ●● | E6: =IF(AND(Activities!$A6<>"",IF(Activities!$E6<>"",ISNUMBER(SEARCH(",3,",","&Activities!$E6&",")),AND(Activities!$C6<=3,Activities!$D6>=3))),IF(Activities!$H6="Coaches","🌱 ",IF(Activities!$H6="Coordinators","⚙️ ",IF(Activities!$H6="Both","👥 ","")))&Activities!$B6&CHAR(10)&REPT("●",Activities!$F6),"") -> 🌱 Unified Funding Application cycle: orientation, troubleshooting, application & purchasing support ●● | F6: =IF(AND(Activities!$A6<>"",IF(Activities!$E6<>"",ISNUMBER(SEARCH(",4,",","&Activities!$E6&",")),AND(Activities!$C6<=4,Activities!$D6>=4))),IF(Activities!$H6="Coaches","🌱 ",IF(Activities!$H6="Coordinators","⚙️ ",IF(Activities!$H6="Both","👥 ","")))&Activities!$B6&CHAR(10)&REPT("●",Activities!$F6),"") -> 🌱 Unified Funding Application cycle: orientation, troubleshooting, application & purchasing support ●● | G6: =IF(AND(Activities!$A6<>"",IF(Activities!$E6<>"",ISNUMBER(SEARCH(",5,",","&Activities!$E6&",")),AND(Activities!$C6<=5,Activities!$D6>=5))),IF(Activities!$H6="Coaches","🌱 ",IF(Activities!$H6="Coordinators","⚙️ ",IF(Activities!$H6="Both","👥 ","")))&Activities!$B6&CHAR(10)&REPT("●",Activities!$F6),"") | H6: =IF(AND(Activities!$A6<>"",IF(Activities!$E6<>"",ISNUMBER(SEARCH(",6,",","&Activities!$E6&",")),AND(Activities!$C6<=6,Activities!$D6>=6))),IF(Activities!$H6="Coaches","🌱 ",IF(Activities!$H6="Coordinators","⚙️ ",IF(Activities!$H6="Both","👥 ","")))&Activities!$B6&CHAR(10)&REPT("●",Activities!$F6),"") | I6: =IF(AND(Activities!$A6<>"",IF(Activities!$E6<>"",ISNUMBER(SEARCH(",7,",","&Activities!$E6&",")),AND(Activities!$C6<=7,Activities!$D6>=7))),IF(Activities!$H6="Coaches","🌱 ",IF(Activities!$H6="Coordinators","⚙️ ",IF(Activities!$H6="Both","👥 ","")))&Activities!$B6&CHAR(10)&REPT("●",Activities!$F6),"") -> 🌱 Unified Funding Application cycle: orientation, troubleshooting, application & purchasing support ●● | J6: =IF(AND(Activities!$A6<>"",IF(Activities!$E6<>"",ISNUMBER(SEARCH(",8,",","&Activities!$E6&",")),AND(Activities!$C6<=8,Activities!$D6>=8))),IF(Activities!$H6="Coaches","🌱 ",IF(Activities!$H6="Coordinators","⚙️ ",IF(Activities!$H6="Both","👥 ","")))&Activities!$B6&CHAR(10)&REPT("●",Activities!$F6),"") -> 🌱 Unified Funding Application cycle: orientation, troubleshooting, application & purchasing support ●● | K6: =IF(AND(Activities!$A6<>"",IF(Activities!$E6<>"",ISNUMBER(SEARCH(",9,",","&Activities!$E6&",")),AND(Activities!$C6<=9,Activities!$D6>=9))),IF(Activities!$H6="Coaches","🌱 ",IF(Activities!$H6="Coordinators","⚙️ ",IF(Activities!$H6="Both","👥 ","")))&Activities!$B6&CHAR(10)&REPT("●",Activities!$F6),"") -> 🌱 Unified Funding Application cycle: orientation, troubleshooting, application & purchasing support ●● | L6: =IF(AND(Activities!$A6<>"",IF(Activities!$E6<>"",ISNUMBER(SEARCH(",10,",","&Activities!$E6&",")),AND(Activities!$C6<=10,Activities!$D6>=10))),IF(Activities!$H6="Coaches","🌱 ",IF(Activities!$H6="Coordinators","⚙️ ",IF(Activities!$H6="Both","👥 ","")))&Activities!$B6&CHAR(10)&REPT("●",Activities!$F6),"") | M6: =IF(AND(Activities!$A6<>"",IF(Activities!$E6<>"",ISNUMBER(SEARCH(",11,",","&Activities!$E6&",")),AND(Activities!$C6<=11,Activities!$D6>=11))),IF(Activities!$H6="Coaches","🌱 ",IF(Activities!$H6="Coordinators","⚙️ ",IF(Activities!$H6="Both","👥 ","")))&Activities!$B6&CHAR(10)&REPT("●",Activities!$F6),"") | N6: =IF(AND(Activities!$A6<>"",IF(Activities!$E6<>"",ISNUMBER(SEARCH(",12,",","&Activities!$E6&",")),AND(Activities!$C6<=12,Activities!$D6>=12))),IF(Activities!$H6="Coaches","🌱 ",IF(Activities!$H6="Coordinators","⚙️ ",IF(Activities!$H6="Both","👥 ","")))&Activities!$B6&CHAR(10)&REPT("●",Activities!$F6),"") -> 🌱 Unified Funding Application cycle: orientation, troubleshooting, application & purchasing support ●●
A7: =IF(Activities!$A7<>"",Activities!$A7,"") -> CTE Pathway, Scheduling & Funding | B7: =IF(Activities!$B7<>"",Activities!$B7,"") -> GSPP planning, implementation & spending support | C7: =IF(AND(Activities!$A7<>"",IF(Activities!$E7<>"",ISNUMBER(SEARCH(",1,",","&Activities!$E7&",")),AND(Activities!$C7<=1,Activities!$D7>=1))),IF(Activities!$H7="Coaches","🌱 ",IF(Activities!$H7="Coordinators","⚙️ ",IF(Activities!$H7="Both","👥 ","")))&Activities!$B7&CHAR(10)&REPT("●",Activities!$F7),"") | D7: =IF(AND(Activities!$A7<>"",IF(Activities!$E7<>"",ISNUMBER(SEARCH(",2,",","&Activities!$E7&",")),AND(Activities!$C7<=2,Activities!$D7>=2))),IF(Activities!$H7="Coaches","🌱 ",IF(Activities!$H7="Coordinators","⚙️ ",IF(Activities!$H7="Both","👥 ","")))&Activities!$B7&CHAR(10)&REPT("●",Activities!$F7),"") | E7: =IF(AND(Activities!$A7<>"",IF(Activities!$E7<>"",ISNUMBER(SEARCH(",3,",","&Activities!$E7&",")),AND(Activities!$C7<=3,Activities!$D7>=3))),IF(Activities!$H7="Coaches","🌱 ",IF(Activities!$H7="Coordinators","⚙️ ",IF(Activities!$H7="Both","👥 ","")))&Activities!$B7&CHAR(10)&REPT("●",Activities!$F7),"") -> 🌱 GSPP planning, implementation & spending support ●● | F7: =IF(AND(Activities!$A7<>"",IF(Activities!$E7<>"",ISNUMBER(SEARCH(",4,",","&Activities!$E7&",")),AND(Activities!$C7<=4,Activities!$D7>=4))),IF(Activities!$H7="Coaches","🌱 ",IF(Activities!$H7="Coordinators","⚙️ ",IF(Activities!$H7="Both","👥 ","")))&Activities!$B7&CHAR(10)&REPT("●",Activities!$F7),"") | G7: =IF(AND(Activities!$A7<>"",IF(Activities!$E7<>"",ISNUMBER(SEARCH(",5,",","&Activities!$E7&",")),AND(Activities!$C7<=5,Activities!$D7>=5))),IF(Activities!$H7="Coaches","🌱 ",IF(Activities!$H7="Coordinators","⚙️ ",IF(Activities!$H7="Both","👥 ","")))&Activities!$B7&CHAR(10)&REPT("●",Activities!$F7),"") -> 🌱 GSPP planning, implementation & spending support ●● | H7: =IF(AND(Activities!$A7<>"",IF(Activities!$E7<>"",ISNUMBER(SEARCH(",6,",","&Activities!$E7&",")),AND(Activities!$C7<=6,Activities!$D7>=6))),IF(Activities!$H7="Coaches","🌱 ",IF(Activities!$H7="Coordinators","⚙️ ",IF(Activities!$H7="Both","👥 ","")))&Activities!$B7&CHAR(10)&REPT("●",Activities!$F7),"") -> 🌱 GSPP planning, implementation & spending support ●● | I7: =IF(AND(Activities!$A7<>"",IF(Activities!$E7<>"",ISNUMBER(SEARCH(",7,",","&Activities!$E7&",")),AND(Activities!$C7<=7,Activities!$D7>=7))),IF(Activities!$H7="Coaches","🌱 ",IF(Activities!$H7="Coordinators","⚙️ ",IF(Activities!$H7="Both","👥 ","")))&Activities!$B7&CHAR(10)&REPT("●",Activities!$F7),"") -> 🌱 GSPP planning, implementation & spending support ●● | J7: =IF(AND(Activities!$A7<>"",IF(Activities!$E7<>"",ISNUMBER(SEARCH(",8,",","&Activities!$E7&",")),AND(Activities!$C7<=8,Activities!$D7>=8))),IF(Activities!$H7="Coaches","🌱 ",IF(Activities!$H7="Coordinators","⚙️ ",IF(Activities!$H7="Both","👥 ","")))&Activities!$B7&CHAR(10)&REPT("●",Activities!$F7),"") -> 🌱 GSPP planning, implementation & spending support ●● | K7: =IF(AND(Activities!$A7<>"",IF(Activities!$E7<>"",ISNUMBER(SEARCH(",9,",","&Activities!$E7&",")),AND(Activities!$C7<=9,Activities!$D7>=9))),IF(Activities!$H7="Coaches","🌱 ",IF(Activities!$H7="Coordinators","⚙️ ",IF(Activities!$H7="Both","👥 ","")))&Activities!$B7&CHAR(10)&REPT("●",Activities!$F7),"") -> 🌱 GSPP planning, implementation & spending support ●● | L7: =IF(AND(Activities!$A7<>"",IF(Activities!$E7<>"",ISNUMBER(SEARCH(",10,",","&Activities!$E7&",")),AND(Activities!$C7<=10,Activities!$D7>=10))),IF(Activities!$H7="Coaches","🌱 ",IF(Activities!$H7="Coordinators","⚙️ ",IF(Activities!$H7="Both","👥 ","")))&Activities!$B7&CHAR(10)&REPT("●",Activities!$F7),"") | M7: =IF(AND(Activities!$A7<>"",IF(Activities!$E7<>"",ISNUMBER(SEARCH(",11,",","&Activities!$E7&",")),AND(Activities!$C7<=11,Activities!$D7>=11))),IF(Activities!$H7="Coaches","🌱 ",IF(Activities!$H7="Coordinators","⚙️ ",IF(Activities!$H7="Both","👥 ","")))&Activities!$B7&CHAR(10)&REPT("●",Activities!$F7),"") -> 🌱 GSPP planning, implementation & spending support ●● | N7: =IF(AND(Activities!$A7<>"",IF(Activities!$E7<>"",ISNUMBER(SEARCH(",12,",","&Activities!$E7&",")),AND(Activities!$C7<=12,Activities!$D7>=12))),IF(Activities!$H7="Coaches","🌱 ",IF(Activities!$H7="Coordinators","⚙️ ",IF(Activities!$H7="Both","👥 ","")))&Activities!$B7&CHAR(10)&REPT("●",Activities!$F7),"") -> 🌱 GSPP planning, implementation & spending support ●●
A8: =IF(Activities!$A8<>"",Activities!$A8,"") -> CTE Pathway, Scheduling & Funding | B8: =IF(Activities!$B8<>"",Activities!$B8,"") -> Course equivalencies development | C8: =IF(AND(Activities!$A8<>"",IF(Activities!$E8<>"",ISNUMBER(SEARCH(",1,",","&Activities!$E8&",")),AND(Activities!$C8<=1,Activities!$D8>=1))),IF(Activities!$H8="Coaches","🌱 ",IF(Activities!$H8="Coordinators","⚙️ ",IF(Activities!$H8="Both","👥 ","")))&Activities!$B8&CHAR(10)&REPT("●",Activities!$F8),"") | D8: =IF(AND(Activities!$A8<>"",IF(Activities!$E8<>"",ISNUMBER(SEARCH(",2,",","&Activities!$E8&",")),AND(Activities!$C8<=2,Activities!$D8>=2))),IF(Activities!$H8="Coaches","🌱 ",IF(Activities!$H8="Coordinators","⚙️ ",IF(Activities!$H8="Both","👥 ","")))&Activities!$B8&CHAR(10)&REPT("●",Activities!$F8),"") -> 🌱 Course equivalencies development ●● | E8: =IF(AND(Activities!$A8<>"",IF(Activities!$E8<>"",ISNUMBER(SEARCH(",3,",","&Activities!$E8&",")),AND(Activities!$C8<=3,Activities!$D8>=3))),IF(Activities!$H8="Coaches","🌱 ",IF(Activities!$H8="Coordinators","⚙️ ",IF(Activities!$H8="Both","👥 ","")))&Activities!$B8&CHAR(10)&REPT("●",Activities!$F8),"") -> 🌱 Course equivalencies development ●● | F8: =IF(AND(Activities!$A8<>"",IF(Activities!$E8<>"",ISNUMBER(SEARCH(",4,",","&Activities!$E8&",")),AND(Activities!$C8<=4,Activities!$D8>=4))),IF(Activities!$H8="Coaches","🌱 ",IF(Activities!$H8="Coordinators","⚙️ ",IF(Activities!$H8="Both","👥 ","")))&Activities!$B8&CHAR(10)&REPT("●",Activities!$F8),"") -> 🌱 Course equivalencies development ●● | G8: =IF(AND(Activities!$A8<>"",IF(Activities!$E8<>"",ISNUMBER(SEARCH(",5,",","&Activities!$E8&",")),AND(Activities!$C8<=5,Activities!$D8>=5))),IF(Activities!$H8="Coaches","🌱 ",IF(Activities!$H8="Coordinators","⚙️ ",IF(Activities!$H8="Both","👥 ","")))&Activities!$B8&CHAR(10)&REPT("●",Activities!$F8),"") -> 🌱 Course equivalencies development ●● | H8: =IF(AND(Activities!$A8<>"",IF(Activities!$E8<>"",ISNUMBER(SEARCH(",6,",","&Activities!$E8&",")),AND(Activities!$C8<=6,Activities!$D8>=6))),IF(Activities!$H8="Coaches","🌱 ",IF(Activities!$H8="Coordinators","⚙️ ",IF(Activities!$H8="Both","👥 ","")))&Activities!$B8&CHAR(10)&REPT("●",Activities!$F8),"") | I8: =IF(AND(Activities!$A8<>"",IF(Activities!$E8<>"",ISNUMBER(SEARCH(",7,",","&Activities!$E8&",")),AND(Activities!$C8<=7,Activities!$D8>=7))),IF(Activities!$H8="Coaches","🌱 ",IF(Activities!$H8="Coordinators","⚙️ ",IF(Activities!$H8="Both","👥 ","")))&Activities!$B8&CHAR(10)&REPT("●",Activities!$F8),"") | J8: =IF(AND(Activities!$A8<>"",IF(Activities!$E8<>"",ISNUMBER(SEARCH(",8,",","&Activities!$E8&",")),AND(Activities!$C8<=8,Activities!$D8>=8))),IF(Activities!$H8="Coaches","🌱 ",IF(Activities!$H8="Coordinators","⚙️ ",IF(Activities!$H8="Both","👥 ","")))&Activities!$B8&CHAR(10)&REPT("●",Activities!$F8),"") | K8: =IF(AND(Activities!$A8<>"",IF(Activities!$E8<>"",ISNUMBER(SEARCH(",9,",","&Activities!$E8&",")),AND(Activities!$C8<=9,Activities!$D8>=9))),IF(Activities!$H8="Coaches","🌱 ",IF(Activities!$H8="Coordinators","⚙️ ",IF(Activities!$H8="Both","👥 ","")))&Activities!$B8&CHAR(10)&REPT("●",Activities!$F8),"") | L8: =IF(AND(Activities!$A8<>"",IF(Activities!$E8<>"",ISNUMBER(SEARCH(",10,",","&Activities!$E8&",")),AND(Activities!$C8<=10,Activities!$D8>=10))),IF(Activities!$H8="Coaches","🌱 ",IF(Activities!$H8="Coordinators","⚙️ ",IF(Activities!$H8="Both","👥 ","")))&Activities!$B8&CHAR(10)&REPT("●",Activities!$F8),"") | M8: =IF(AND(Activities!$A8<>"",IF(Activities!$E8<>"",ISNUMBER(SEARCH(",11,",","&Activities!$E8&",")),AND(Activities!$C8<=11,Activities!$D8>=11))),IF(Activities!$H8="Coaches","🌱 ",IF(Activities!$H8="Coordinators","⚙️ ",IF(Activities!$H8="Both","👥 ","")))&Activities!$B8&CHAR(10)&REPT("●",Activities!$F8),"") | N8: =IF(AND(Activities!$A8<>"",IF(Activities!$E8<>"",ISNUMBER(SEARCH(",12,",","&Activities!$E8&",")),AND(Activities!$C8<=12,Activities!$D8>=12))),IF(Activities!$H8="Coaches","🌱 ",IF(Activities!$H8="Coordinators","⚙️ ",IF(Activities!$H8="Both","👥 ","")))&Activities!$B8&CHAR(10)&REPT("●",Activities!$F8),"")
A9: =IF(Activities!$A9<>"",Activities!$A9,"") -> Instructional Design, PBL & Defenses | B9: =IF(Activities!$B9<>"",Activities!$B9,"") -> PBL/HQIM annual planning, pilot reflection & improvement design | C9: =IF(AND(Activities!$A9<>"",IF(Activities!$E9<>"",ISNUMBER(SEARCH(",1,",","&Activities!$E9&",")),AND(Activities!$C9<=1,Activities!$D9>=1))),IF(Activities!$H9="Coaches","🌱 ",IF(Activities!$H9="Coordinators","⚙️ ",IF(Activities!$H9="Both","👥 ","")))&Activities!$B9&CHAR(10)&REPT("●",Activities!$F9),"") | D9: =IF(AND(Activities!$A9<>"",IF(Activities!$E9<>"",ISNUMBER(SEARCH(",2,",","&Activities!$E9&",")),AND(Activities!$C9<=2,Activities!$D9>=2))),IF(Activities!$H9="Coaches","🌱 ",IF(Activities!$H9="Coordinators","⚙️ ",IF(Activities!$H9="Both","👥 ","")))&Activities!$B9&CHAR(10)&REPT("●",Activities!$F9),"") | E9: =IF(AND(Activities!$A9<>"",IF(Activities!$E9<>"",ISNUMBER(SEARCH(",3,",","&Activities!$E9&",")),AND(Activities!$C9<=3,Activities!$D9>=3))),IF(Activities!$H9="Coaches","🌱 ",IF(Activities!$H9="Coordinators","⚙️ ",IF(Activities!$H9="Both","👥 ","")))&Activities!$B9&CHAR(10)&REPT("●",Activities!$F9),"") | F9: =IF(AND(Activities!$A9<>"",IF(Activities!$E9<>"",ISNUMBER(SEARCH(",4,",","&Activities!$E9&",")),AND(Activities!$C9<=4,Activities!$D9>=4))),IF(Activities!$H9="Coaches","🌱 ",IF(Activities!$H9="Coordinators","⚙️ ",IF(Activities!$H9="Both","👥 ","")))&Activities!$B9&CHAR(10)&REPT("●",Activities!$F9),"") | G9: =IF(AND(Activities!$A9<>"",IF(Activities!$E9<>"",ISNUMBER(SEARCH(",5,",","&Activities!$E9&",")),AND(Activities!$C9<=5,Activities!$D9>=5))),IF(Activities!$H9="Coaches","🌱 ",IF(Activities!$H9="Coordinators","⚙️ ",IF(Activities!$H9="Both","👥 ","")))&Activities!$B9&CHAR(10)&REPT("●",Activities!$F9),"") | H9: =IF(AND(Activities!$A9<>"",IF(Activities!$E9<>"",ISNUMBER(SEARCH(",6,",","&Activities!$E9&",")),AND(Activities!$C9<=6,Activities!$D9>=6))),IF(Activities!$H9="Coaches","🌱 ",IF(Activities!$H9="Coordinators","⚙️ ",IF(Activities!$H9="Both","👥 ","")))&Activities!$B9&CHAR(10)&REPT("●",Activities!$F9),"") | I9: =IF(AND(Activities!$A9<>"",IF(Activities!$E9<>"",ISNUMBER(SEARCH(",7,",","&Activities!$E9&",")),AND(Activities!$C9<=7,Activities!$D9>=7))),IF(Activities!$H9="Coaches","🌱 ",IF(Activities!$H9="Coordinators","⚙️ ",IF(Activities!$H9="Both","👥 ","")))&Activities!$B9&CHAR(10)&REPT("●",Activities!$F9),"") | J9: =IF(AND(Activities!$A9<>"",IF(Activities!$E9<>"",ISNUMBER(SEARCH(",8,",","&Activities!$E9&",")),AND(Activities!$C9<=8,Activities!$D9>=8))),IF(Activities!$H9="Coaches","🌱 ",IF(Activities!$H9="Coordinators","⚙️ ",IF(Activities!$H9="Both","👥 ","")))&Activities!$B9&CHAR(10)&REPT("●",Activities!$F9),"") | K9: =IF(AND(Activities!$A9<>"",IF(Activities!$E9<>"",ISNUMBER(SEARCH(",9,",","&Activities!$E9&",")),AND(Activities!$C9<=9,Activities!$D9>=9))),IF(Activities!$H9="Coaches","🌱 ",IF(Activities!$H9="Coordinators","⚙️ ",IF(Activities!$H9="Both","👥 ","")))&Activities!$B9&CHAR(10)&REPT("●",Activities!$F9),"") | L9: =IF(AND(Activities!$A9<>"",IF(Activities!$E9<>"",ISNUMBER(SEARCH(",10,",","&Activities!$E9&",")),AND(Activities!$C9<=10,Activities!$D9>=10))),IF(Activities!$H9="Coaches","🌱 ",IF(Activities!$H9="Coordinators","⚙️ ",IF(Activities!$H9="Both","👥 ","")))&Activities!$B9&CHAR(10)&REPT("●",Activities!$F9),"") | M9: =IF(AND(Activities!$A9<>"",IF(Activities!$E9<>"",ISNUMBER(SEARCH(",11,",","&Activities!$E9&",")),AND(Activities!$C9<=11,Activities!$D9>=11))),IF(Activities!$H9="Coaches","🌱 ",IF(Activities!$H9="Coordinators","⚙️ ",IF(Activities!$H9="Both","👥 ","")))&Activities!$B9&CHAR(10)&REPT("●",Activities!$F9),"") -> 🌱 PBL/HQIM annual planning, pilot reflection & improvement design ● | N9: =IF(AND(Activities!$A9<>"",IF(Activities!$E9<>"",ISNUMBER(SEARCH(",12,",","&Activities!$E9&",")),AND(Activities!$C9<=12,Activities!$D9>=12))),IF(Activities!$H9="Coaches","🌱 ",IF(Activities!$H9="Coordinators","⚙️ ",IF(Activities!$H9="Both","👥 ","")))&Activities!$B9&CHAR(10)&REPT("●",Activities!$F9),"") -> 🌱 PBL/HQIM annual planning, pilot reflection & improvement design ●
A10: =IF(Activities!$A10<>"",Activities!$A10,"") -> Instructional Design, PBL & Defenses | B10: =IF(Activities!$B10<>"",Activities!$B10,"") -> PBL/HQIM school-site coaching and professional learning | C10: =IF(AND(Activities!$A10<>"",IF(Activities!$E10<>"",ISNUMBER(SEARCH(",1,",","&Activities!$E10&",")),AND(Activities!$C10<=1,Activities!$D10>=1))),IF(Activities!$H10="Coaches","🌱 ",IF(Activities!$H10="Coordinators","⚙️ ",IF(Activities!$H10="Both","👥 ","")))&Activities!$B10&CHAR(10)&REPT("●",Activities!$F10),"") | D10: =IF(AND(Activities!$A10<>"",IF(Activities!$E10<>"",ISNUMBER(SEARCH(",2,",","&Activities!$E10&",")),AND(Activities!$C10<=2,Activities!$D10>=2))),IF(Activities!$H10="Coaches","🌱 ",IF(Activities!$H10="Coordinators","⚙️ ",IF(Activities!$H10="Both","👥 ","")))&Activities!$B10&CHAR(10)&REPT("●",Activities!$F10),"") | E10: =IF(AND(Activities!$A10<>"",IF(Activities!$E10<>"",ISNUMBER(SEARCH(",3,",","&Activities!$E10&",")),AND(Activities!$C10<=3,Activities!$D10>=3))),IF(Activities!$H10="Coaches","🌱 ",IF(Activities!$H10="Coordinators","⚙️ ",IF(Activities!$H10="Both","👥 ","")))&Activities!$B10&CHAR(10)&REPT("●",Activities!$F10),"") -> 🌱 PBL/HQIM school-site coaching and professional learning ●●● | F10: =IF(AND(Activities!$A10<>"",IF(Activities!$E10<>"",ISNUMBER(SEARCH(",4,",","&Activities!$E10&",")),AND(Activities!$C10<=4,Activities!$D10>=4))),IF(Activities!$H10="Coaches","🌱 ",IF(Activities!$H10="Coordinators","⚙️ ",IF(Activities!$H10="Both","👥 ","")))&Activities!$B10&CHAR(10)&REPT("●",Activities!$F10),"") -> 🌱 PBL/HQIM school-site coaching and professional learning ●●● | G10: =IF(AND(Activities!$A10<>"",IF(Activities!$E10<>"",ISNUMBER(SEARCH(",5,",","&Activities!$E10&",")),AND(Activities!$C10<=5,Activities!$D10>=5))),IF(Activities!$H10="Coaches","🌱 ",IF(Activities!$H10="Coordinators","⚙️ ",IF(Activities!$H10="Both","👥 ","")))&Activities!$B10&CHAR(10)&REPT("●",Activities!$F10),"") -> 🌱 PBL/HQIM school-site coaching and professional learning ●●● | H10: =IF(AND(Activities!$A10<>"",IF(Activities!$E10<>"",ISNUMBER(SEARCH(",6,",","&Activities!$E10&",")),AND(Activities!$C10<=6,Activities!$D10>=6))),IF(Activities!$H10="Coaches","🌱 ",IF(Activities!$H10="Coordinators","⚙️ ",IF(Activities!$H10="Both","👥 ","")))&Activities!$B10&CHAR(10)&REPT("●",Activities!$F10),"") -> 🌱 PBL/HQIM school-site coaching and professional learning ●●● | I10: =IF(AND(Activities!$A10<>"",IF(Activities!$E10<>"",ISNUMBER(SEARCH(",7,",","&Activities!$E10&",")),AND(Activities!$C10<=7,Activities!$D10>=7))),IF(Activities!$H10="Coaches","🌱 ",IF(Activities!$H10="Coordinators","⚙️ ",IF(Activities!$H10="Both","👥 ","")))&Activities!$B10&CHAR(10)&REPT("●",Activities!$F10),"") -> 🌱 PBL/HQIM school-site coaching and professional learning ●●● | J10: =IF(AND(Activities!$A10<>"",IF(Activities!$E10<>"",ISNUMBER(SEARCH(",8,",","&Activities!$E10&",")),AND(Activities!$C10<=8,Activities!$D10>=8))),IF(Activities!$H10="Coaches","🌱 ",IF(Activities!$H10="Coordinators","⚙️ ",IF(Activities!$H10="Both","👥 ","")))&Activities!$B10&CHAR(10)&REPT("●",Activities!$F10),"") -> 🌱 PBL/HQIM school-site coaching and professional learning ●●● | K10: =IF(AND(Activities!$A10<>"",IF(Activities!$E10<>"",ISNUMBER(SEARCH(",9,",","&Activities!$E10&",")),AND(Activities!$C10<=9,Activities!$D10>=9))),IF(Activities!$H10="Coaches","🌱 ",IF(Activities!$H10="Coordinators","⚙️ ",IF(Activities!$H10="Both","👥 ","")))&Activities!$B10&CHAR(10)&REPT("●",Activities!$F10),"") -> 🌱 PBL/HQIM school-site coaching and professional learning ●●● | L10: =IF(AND(Activities!$A10<>"",IF(Activities!$E10<>"",ISNUMBER(SEARCH(",10,",","&Activities!$E10&",")),AND(Activities!$C10<=10,Activities!$D10>=10))),IF(Activities!$H10="Coaches","🌱 ",IF(Activities!$H10="Coordinators","⚙️ ",IF(Activities!$H10="Both","👥 ","")))&Activities!$B10&CHAR(10)&REPT("●",Activities!$F10),"") | M10: =IF(AND(Activities!$A10<>"",IF(Activities!$E10<>"",ISNUMBER(SEARCH(",11,",","&Activities!$E10&",")),AND(Activities!$C10<=11,Activities!$D10>=11))),IF(Activities!$H10="Coaches","🌱 ",IF(Activities!$H10="Coordinators","⚙️ ",IF(Activities!$H10="Both","👥 ","")))&Activities!$B10&CHAR(10)&REPT("●",Activities!$F10),"") | N10: =IF(AND(Activities!$A10<>"",IF(Activities!$E10<>"",ISNUMBER(SEARCH(",12,",","&Activities!$E10&",")),AND(Activities!$C10<=12,Activities!$D10>=12))),IF(Activities!$H10="Coaches","🌱 ",IF(Activities!$H10="Coordinators","⚙️ ",IF(Activities!$H10="Both","👥 ","")))&Activities!$B10&CHAR(10)&REPT("●",Activities!$F10),"")
A11: =IF(Activities!$A11<>"",Activities!$A11,"") -> Instructional Design, PBL & Defenses | B11: =IF(Activities!$B11<>"",Activities!$B11,"") -> Linked Learning onboarding / August PBL professional learning | C11: =IF(AND(Activities!$A11<>"",IF(Activities!$E11<>"",ISNUMBER(SEARCH(",1,",","&Activities!$E11&",")),AND(Activities!$C11<=1,Activities!$D11>=1))),IF(Activities!$H11="Coaches","🌱 ",IF(Activities!$H11="Coordinators","⚙️ ",IF(Activities!$H11="Both","👥 ","")))&Activities!$B11&CHAR(10)&REPT("●",Activities!$F11),"") | D11: =IF(AND(Activities!$A11<>"",IF(Activities!$E11<>"",ISNUMBER(SEARCH(",2,",","&Activities!$E11&",")),AND(Activities!$C11<=2,Activities!$D11>=2))),IF(Activities!$H11="Coaches","🌱 ",IF(Activities!$H11="Coordinators","⚙️ ",IF(Activities!$H11="Both","👥 ","")))&Activities!$B11&CHAR(10)&REPT("●",Activities!$F11),"") -> 🌱 Linked Learning onboarding / August PBL professional learning ●● | E11: =IF(AND(Activities!$A11<>"",IF(Activities!$E11<>"",ISNUMBER(SEARCH(",3,",","&Activities!$E11&",")),AND(Activities!$C11<=3,Activities!$D11>=3))),IF(Activities!$H11="Coaches","🌱 ",IF(Activities!$H11="Coordinators","⚙️ ",IF(Activities!$H11="Both","👥 ","")))&Activities!$B11&CHAR(10)&REPT("●",Activities!$F11),"") | F11: =IF(AND(Activities!$A11<>"",IF(Activities!$E11<>"",ISNUMBER(SEARCH(",4,",","&Activities!$E11&",")),AND(Activities!$C11<=4,Activities!$D11>=4))),IF(Activities!$H11="Coaches","🌱 ",IF(Activities!$H11="Coordinators","⚙️ ",IF(Activities!$H11="Both","👥 ","")))&Activities!$B11&CHAR(10)&REPT("●",Activities!$F11),"") | G11: =IF(AND(Activities!$A11<>"",IF(Activities!$E11<>"",ISNUMBER(SEARCH(",5,",","&Activities!$E11&",")),AND(Activities!$C11<=5,Activities!$D11>=5))),IF(Activities!$H11="Coaches","🌱 ",IF(Activities!$H11="Coordinators","⚙️ ",IF(Activities!$H11="Both","👥 ","")))&Activities!$B11&CHAR(10)&REPT("●",Activities!$F11),"") | H11: =IF(AND(Activities!$A11<>"",IF(Activities!$E11<>"",ISNUMBER(SEARCH(",6,",","&Activities!$E11&",")),AND(Activities!$C11<=6,Activities!$D11>=6))),IF(Activities!$H11="Coaches","🌱 ",IF(Activities!$H11="Coordinators","⚙️ ",IF(Activities!$H11="Both","👥 ","")))&Activities!$B11&CHAR(10)&REPT("●",Activities!$F11),"") | I11: =IF(AND(Activities!$A11<>"",IF(Activities!$E11<>"",ISNUMBER(SEARCH(",7,",","&Activities!$E11&",")),AND(Activities!$C11<=7,Activities!$D11>=7))),IF(Activities!$H11="Coaches","🌱 ",IF(Activities!$H11="Coordinators","⚙️ ",IF(Activities!$H11="Both","👥 ","")))&Activities!$B11&CHAR(10)&REPT("●",Activities!$F11),"") | J11: =IF(AND(Activities!$A11<>"",IF(Activities!$E11<>"",ISNUMBER(SEARCH(",8,",","&Activities!$E11&",")),AND(Activities!$C11<=8,Activities!$D11>=8))),IF(Activities!$H11="Coaches","🌱 ",IF(Activities!$H11="Coordinators","⚙️ ",IF(Activities!$H11="Both","👥 ","")))&Activities!$B11&CHAR(10)&REPT("●",Activities!$F11),"") | K11: =IF(AND(Activities!$A11<>"",IF(Activities!$E11<>"",ISNUMBER(SEARCH(",9,",","&Activities!$E11&",")),AND(Activities!$C11<=9,Activities!$D11>=9))),IF(Activities!$H11="Coaches","🌱 ",IF(Activities!$H11="Coordinators","⚙️ ",IF(Activities!$H11="Both","👥 ","")))&Activities!$B11&CHAR(10)&REPT("●",Activities!$F11),"") | L11: =IF(AND(Activities!$A11<>"",IF(Activities!$E11<>"",ISNUMBER(SEARCH(",10,",","&Activities!$E11&",")),AND(Activities!$C11<=10,Activities!$D11>=10))),IF(Activities!$H11="Coaches","🌱 ",IF(Activities!$H11="Coordinators","⚙️ ",IF(Activities!$H11="Both","👥 ","")))&Activities!$B11&CHAR(10)&REPT("●",Activities!$F11),"") | M11: =IF(AND(Activities!$A11<>"",IF(Activities!$E11<>"",ISNUMBER(SEARCH(",11,",","&Activities!$E11&",")),AND(Activities!$C11<=11,Activities!$D11>=11))),IF(Activities!$H11="Coaches","🌱 ",IF(Activities!$H11="Coordinators","⚙️ ",IF(Activities!$H11="Both","👥 ","")))&Activities!$B11&CHAR(10)&REPT("●",Activities!$F11),"") | N11: =IF(AND(Activities!$A11<>"",IF(Activities!$E11<>"",ISNUMBER(SEARCH(",12,",","&Activities!$E11&",")),AND(Activities!$C11<=12,Activities!$D11>=12))),IF(Activities!$H11="Coaches","🌱 ",IF(Activities!$H11="Coordinators","⚙️ ",IF(Activities!$H11="Both","👥 ","")))&Activities!$B11&CHAR(10)&REPT("●",Activities!$F11),"")
A12: =IF(Activities!$A12<>"",Activities!$A12,"") -> Instructional Design, PBL & Defenses | B12: =IF(Activities!$B12<>"",Activities!$B12,"") -> PBL 101 / fall instructional training | C12: =IF(AND(Activities!$A12<>"",IF(Activities!$E12<>"",ISNUMBER(SEARCH(",1,",","&Activities!$E12&",")),AND(Activities!$C12<=1,Activities!$D12>=1))),IF(Activities!$H12="Coaches","🌱 ",IF(Activities!$H12="Coordinators","⚙️ ",IF(Activities!$H12="Both","👥 ","")))&Activities!$B12&CHAR(10)&REPT("●",Activities!$F12),"") | D12: =IF(AND(Activities!$A12<>"",IF(Activities!$E12<>"",ISNUMBER(SEARCH(",2,",","&Activities!$E12&",")),AND(Activities!$C12<=2,Activities!$D12>=2))),IF(Activities!$H12="Coaches","🌱 ",IF(Activities!$H12="Coordinators","⚙️ ",IF(Activities!$H12="Both","👥 ","")))&Activities!$B12&CHAR(10)&REPT("●",Activities!$F12),"") | E12: =IF(AND(Activities!$A12<>"",IF(Activities!$E12<>"",ISNUMBER(SEARCH(",3,",","&Activities!$E12&",")),AND(Activities!$C12<=3,Activities!$D12>=3))),IF(Activities!$H12="Coaches","🌱 ",IF(Activities!$H12="Coordinators","⚙️ ",IF(Activities!$H12="Both","👥 ","")))&Activities!$B12&CHAR(10)&REPT("●",Activities!$F12),"") | F12: =IF(AND(Activities!$A12<>"",IF(Activities!$E12<>"",ISNUMBER(SEARCH(",4,",","&Activities!$E12&",")),AND(Activities!$C12<=4,Activities!$D12>=4))),IF(Activities!$H12="Coaches","🌱 ",IF(Activities!$H12="Coordinators","⚙️ ",IF(Activities!$H12="Both","👥 ","")))&Activities!$B12&CHAR(10)&REPT("●",Activities!$F12),"") -> 🌱 PBL 101 / fall instructional training ●●● | G12: =IF(AND(Activities!$A12<>"",IF(Activities!$E12<>"",ISNUMBER(SEARCH(",5,",","&Activities!$E12&",")),AND(Activities!$C12<=5,Activities!$D12>=5))),IF(Activities!$H12="Coaches","🌱 ",IF(Activities!$H12="Coordinators","⚙️ ",IF(Activities!$H12="Both","👥 ","")))&Activities!$B12&CHAR(10)&REPT("●",Activities!$F12),"") | H12: =IF(AND(Activities!$A12<>"",IF(Activities!$E12<>"",ISNUMBER(SEARCH(",6,",","&Activities!$E12&",")),AND(Activities!$C12<=6,Activities!$D12>=6))),IF(Activities!$H12="Coaches","🌱 ",IF(Activities!$H12="Coordinators","⚙️ ",IF(Activities!$H12="Both","👥 ","")))&Activities!$B12&CHAR(10)&REPT("●",Activities!$F12),"") | I12: =IF(AND(Activities!$A12<>"",IF(Activities!$E12<>"",ISNUMBER(SEARCH(",7,",","&Activities!$E12&",")),AND(Activities!$C12<=7,Activities!$D12>=7))),IF(Activities!$H12="Coaches","🌱 ",IF(Activities!$H12="Coordinators","⚙️ ",IF(Activities!$H12="Both","👥 ","")))&Activities!$B12&CHAR(10)&REPT("●",Activities!$F12),"") | J12: =IF(AND(Activities!$A12<>"",IF(Activities!$E12<>"",ISNUMBER(SEARCH(",8,",","&Activities!$E12&",")),AND(Activities!$C12<=8,Activities!$D12>=8))),IF(Activities!$H12="Coaches","🌱 ",IF(Activities!$H12="Coordinators","⚙️ ",IF(Activities!$H12="Both","👥 ","")))&Activities!$B12&CHAR(10)&REPT("●",Activities!$F12),"") | K12: =IF(AND(Activities!$A12<>"",IF(Activities!$E12<>"",ISNUMBER(SEARCH(",9,",","&Activities!$E12&",")),AND(Activities!$C12<=9,Activities!$D12>=9))),IF(Activities!$H12="Coaches","🌱 ",IF(Activities!$H12="Coordinators","⚙️ ",IF(Activities!$H12="Both","👥 ","")))&Activities!$B12&CHAR(10)&REPT("●",Activities!$F12),"") | L12: =IF(AND(Activities!$A12<>"",IF(Activities!$E12<>"",ISNUMBER(SEARCH(",10,",","&Activities!$E12&",")),AND(Activities!$C12<=10,Activities!$D12>=10))),IF(Activities!$H12="Coaches","🌱 ",IF(Activities!$H12="Coordinators","⚙️ ",IF(Activities!$H12="Both","👥 ","")))&Activities!$B12&CHAR(10)&REPT("●",Activities!$F12),"") | M12: =IF(AND(Activities!$A12<>"",IF(Activities!$E12<>"",ISNUMBER(SEARCH(",11,",","&Activities!$E12&",")),AND(Activities!$C12<=11,Activities!$D12>=11))),IF(Activities!$H12="Coaches","🌱 ",IF(Activities!$H12="Coordinators","⚙️ ",IF(Activities!$H12="Both","👥 ","")))&Activities!$B12&CHAR(10)&REPT("●",Activities!$F12),"") | N12: =IF(AND(Activities!$A12<>"",IF(Activities!$E12<>"",ISNUMBER(SEARCH(",12,",","&Activities!$E12&",")),AND(Activities!$C12<=12,Activities!$D12>=12))),IF(Activities!$H12="Coaches","🌱 ",IF(Activities!$H12="Coordinators","⚙️ ",IF(Activities!$H12="Both","👥 ","")))&Activities!$B12&CHAR(10)&REPT("●",Activities!$F12),"")
A13: =IF(Activities!$A13<>"",Activities!$A13,"") -> Instructional Design, PBL & Defenses | B13: =IF(Activities!$B13<>"",Activities!$B13,"") -> Defense calibration, support, feedback & reflection | C13: =IF(AND(Activities!$A13<>"",IF(Activities!$E13<>"",ISNUMBER(SEARCH(",1,",","&Activities!$E13&",")),AND(Activities!$C13<=1,Activities!$D13>=1))),IF(Activities!$H13="Coaches","🌱 ",IF(Activities!$H13="Coordinators","⚙️ ",IF(Activities!$H13="Both","👥 ","")))&Activities!$B13&CHAR(10)&REPT("●",Activities!$F13),"") | D13: =IF(AND(Activities!$A13<>"",IF(Activities!$E13<>"",ISNUMBER(SEARCH(",2,",","&Activities!$E13&",")),AND(Activities!$C13<=2,Activities!$D13>=2))),IF(Activities!$H13="Coaches","🌱 ",IF(Activities!$H13="Coordinators","⚙️ ",IF(Activities!$H13="Both","👥 ","")))&Activities!$B13&CHAR(10)&REPT("●",Activities!$F13),"") | E13: =IF(AND(Activities!$A13<>"",IF(Activities!$E13<>"",ISNUMBER(SEARCH(",3,",","&Activities!$E13&",")),AND(Activities!$C13<=3,Activities!$D13>=3))),IF(Activities!$H13="Coaches","🌱 ",IF(Activities!$H13="Coordinators","⚙️ ",IF(Activities!$H13="Both","👥 ","")))&Activities!$B13&CHAR(10)&REPT("●",Activities!$F13),"") | F13: =IF(AND(Activities!$A13<>"",IF(Activities!$E13<>"",ISNUMBER(SEARCH(",4,",","&Activities!$E13&",")),AND(Activities!$C13<=4,Activities!$D13>=4))),IF(Activities!$H13="Coaches","🌱 ",IF(Activities!$H13="Coordinators","⚙️ ",IF(Activities!$H13="Both","👥 ","")))&Activities!$B13&CHAR(10)&REPT("●",Activities!$F13),"") | G13: =IF(AND(Activities!$A13<>"",IF(Activities!$E13<>"",ISNUMBER(SEARCH(",5,",","&Activities!$E13&",")),AND(Activities!$C13<=5,Activities!$D13>=5))),IF(Activities!$H13="Coaches","🌱 ",IF(Activities!$H13="Coordinators","⚙️ ",IF(Activities!$H13="Both","👥 ","")))&Activities!$B13&CHAR(10)&REPT("●",Activities!$F13),"") | H13: =IF(AND(Activities!$A13<>"",IF(Activities!$E13<>"",ISNUMBER(SEARCH(",6,",","&Activities!$E13&",")),AND(Activities!$C13<=6,Activities!$D13>=6))),IF(Activities!$H13="Coaches","🌱 ",IF(Activities!$H13="Coordinators","⚙️ ",IF(Activities!$H13="Both","👥 ","")))&Activities!$B13&CHAR(10)&REPT("●",Activities!$F13),"") | I13: =IF(AND(Activities!$A13<>"",IF(Activities!$E13<>"",ISNUMBER(SEARCH(",7,",","&Activities!$E13&",")),AND(Activities!$C13<=7,Activities!$D13>=7))),IF(Activities!$H13="Coaches","🌱 ",IF(Activities!$H13="Coordinators","⚙️ ",IF(Activities!$H13="Both","👥 ","")))&Activities!$B13&CHAR(10)&REPT("●",Activities!$F13),"") -> 🌱 Defense calibration, support, feedback & reflection ●● | J13: =IF(AND(Activities!$A13<>"",IF(Activities!$E13<>"",ISNUMBER(SEARCH(",8,",","&Activities!$E13&",")),AND(Activities!$C13<=8,Activities!$D13>=8))),IF(Activities!$H13="Coaches","🌱 ",IF(Activities!$H13="Coordinators","⚙️ ",IF(Activities!$H13="Both","👥 ","")))&Activities!$B13&CHAR(10)&REPT("●",Activities!$F13),"") -> 🌱 Defense calibration, support, feedback & reflection ●● | K13: =IF(AND(Activities!$A13<>"",IF(Activities!$E13<>"",ISNUMBER(SEARCH(",9,",","&Activities!$E13&",")),AND(Activities!$C13<=9,Activities!$D13>=9))),IF(Activities!$H13="Coaches","🌱 ",IF(Activities!$H13="Coordinators","⚙️ ",IF(Activities!$H13="Both","👥 ","")))&Activities!$B13&CHAR(10)&REPT("●",Activities!$F13),"") -> 🌱 Defense calibration, support, feedback & reflection ●● | L13: =IF(AND(Activities!$A13<>"",IF(Activities!$E13<>"",ISNUMBER(SEARCH(",10,",","&Activities!$E13&",")),AND(Activities!$C13<=10,Activities!$D13>=10))),IF(Activities!$H13="Coaches","🌱 ",IF(Activities!$H13="Coordinators","⚙️ ",IF(Activities!$H13="Both","👥 ","")))&Activities!$B13&CHAR(10)&REPT("●",Activities!$F13),"") | M13: =IF(AND(Activities!$A13<>"",IF(Activities!$E13<>"",ISNUMBER(SEARCH(",11,",","&Activities!$E13&",")),AND(Activities!$C13<=11,Activities!$D13>=11))),IF(Activities!$H13="Coaches","🌱 ",IF(Activities!$H13="Coordinators","⚙️ ",IF(Activities!$H13="Both","👥 ","")))&Activities!$B13&CHAR(10)&REPT("●",Activities!$F13),"") -> 🌱 Defense calibration, support, feedback & reflection ●● | N13: =IF(AND(Activities!$A13<>"",IF(Activities!$E13<>"",ISNUMBER(SEARCH(",12,",","&Activities!$E13&",")),AND(Activities!$C13<=12,Activities!$D13>=12))),IF(Activities!$H13="Coaches","🌱 ",IF(Activities!$H13="Coordinators","⚙️ ",IF(Activities!$H13="Both","👥 ","")))&Activities!$B13&CHAR(10)&REPT("●",Activities!$F13),"")
A14: =IF(Activities!$A14<>"",Activities!$A14,"") -> Pathway Strategy, Data & Certification | B14: =IF(Activities!$B14<>"",Activities!$B14,"") -> Administrator goal-setting, priorities & annual data review | C14: =IF(AND(Activities!$A14<>"",IF(Activities!$E14<>"",ISNUMBER(SEARCH(",1,",","&Activities!$E14&",")),AND(Activities!$C14<=1,Activities!$D14>=1))),IF(Activities!$H14="Coaches","🌱 ",IF(Activities!$H14="Coordinators","⚙️ ",IF(Activities!$H14="Both","👥 ","")))&Activities!$B14&CHAR(10)&REPT("●",Activities!$F14),"") -> 👥 Administrator goal-setting, priorities & annual data review ●● | D14: =IF(AND(Activities!$A14<>"",IF(Activities!$E14<>"",ISNUMBER(SEARCH(",2,",","&Activities!$E14&",")),AND(Activities!$C14<=2,Activities!$D14>=2))),IF(Activities!$H14="Coaches","🌱 ",IF(Activities!$H14="Coordinators","⚙️ ",IF(Activities!$H14="Both","👥 ","")))&Activities!$B14&CHAR(10)&REPT("●",Activities!$F14),"") -> 👥 Administrator goal-setting, priorities & annual data review ●● | E14: =IF(AND(Activities!$A14<>"",IF(Activities!$E14<>"",ISNUMBER(SEARCH(",3,",","&Activities!$E14&",")),AND(Activities!$C14<=3,Activities!$D14>=3))),IF(Activities!$H14="Coaches","🌱 ",IF(Activities!$H14="Coordinators","⚙️ ",IF(Activities!$H14="Both","👥 ","")))&Activities!$B14&CHAR(10)&REPT("●",Activities!$F14),"") | F14: =IF(AND(Activities!$A14<>"",IF(Activities!$E14<>"",ISNUMBER(SEARCH(",4,",","&Activities!$E14&",")),AND(Activities!$C14<=4,Activities!$D14>=4))),IF(Activities!$H14="Coaches","🌱 ",IF(Activities!$H14="Coordinators","⚙️ ",IF(Activities!$H14="Both","👥 ","")))&Activities!$B14&CHAR(10)&REPT("●",Activities!$F14),"") | G14: =IF(AND(Activities!$A14<>"",IF(Activities!$E14<>"",ISNUMBER(SEARCH(",5,",","&Activities!$E14&",")),AND(Activities!$C14<=5,Activities!$D14>=5))),IF(Activities!$H14="Coaches","🌱 ",IF(Activities!$H14="Coordinators","⚙️ ",IF(Activities!$H14="Both","👥 ","")))&Activities!$B14&CHAR(10)&REPT("●",Activities!$F14),"") | H14: =IF(AND(Activities!$A14<>"",IF(Activities!$E14<>"",ISNUMBER(SEARCH(",6,",","&Activities!$E14&",")),AND(Activities!$C14<=6,Activities!$D14>=6))),IF(Activities!$H14="Coaches","🌱 ",IF(Activities!$H14="Coordinators","⚙️ ",IF(Activities!$H14="Both","👥 ","")))&Activities!$B14&CHAR(10)&REPT("●",Activities!$F14),"") | I14: =IF(AND(Activities!$A14<>"",IF(Activities!$E14<>"",ISNUMBER(SEARCH(",7,",","&Activities!$E14&",")),AND(Activities!$C14<=7,Activities!$D14>=7))),IF(Activities!$H14="Coaches","🌱 ",IF(Activities!$H14="Coordinators","⚙️ ",IF(Activities!$H14="Both","👥 ","")))&Activities!$B14&CHAR(10)&REPT("●",Activities!$F14),"") | J14: =IF(AND(Activities!$A14<>"",IF(Activities!$E14<>"",ISNUMBER(SEARCH(",8,",","&Activities!$E14&",")),AND(Activities!$C14<=8,Activities!$D14>=8))),IF(Activities!$H14="Coaches","🌱 ",IF(Activities!$H14="Coordinators","⚙️ ",IF(Activities!$H14="Both","👥 ","")))&Activities!$B14&CHAR(10)&REPT("●",Activities!$F14),"") | K14: =IF(AND(Activities!$A14<>"",IF(Activities!$E14<>"",ISNUMBER(SEARCH(",9,",","&Activities!$E14&",")),AND(Activities!$C14<=9,Activities!$D14>=9))),IF(Activities!$H14="Coaches","🌱 ",IF(Activities!$H14="Coordinators","⚙️ ",IF(Activities!$H14="Both","👥 ","")))&Activities!$B14&CHAR(10)&REPT("●",Activities!$F14),"") | L14: =IF(AND(Activities!$A14<>"",IF(Activities!$E14<>"",ISNUMBER(SEARCH(",10,",","&Activities!$E14&",")),AND(Activities!$C14<=10,Activities!$D14>=10))),IF(Activities!$H14="Coaches","🌱 ",IF(Activities!$H14="Coordinators","⚙️ ",IF(Activities!$H14="Both","👥 ","")))&Activities!$B14&CHAR(10)&REPT("●",Activities!$F14),"") | M14: =IF(AND(Activities!$A14<>"",IF(Activities!$E14<>"",ISNUMBER(SEARCH(",11,",","&Activities!$E14&",")),AND(Activities!$C14<=11,Activities!$D14>=11))),IF(Activities!$H14="Coaches","🌱 ",IF(Activities!$H14="Coordinators","⚙️ ",IF(Activities!$H14="Both","👥 ","")))&Activities!$B14&CHAR(10)&REPT("●",Activities!$F14),"") | N14: =IF(AND(Activities!$A14<>"",IF(Activities!$E14<>"",ISNUMBER(SEARCH(",12,",","&Activities!$E14&",")),AND(Activities!$C14<=12,Activities!$D14>=12))),IF(Activities!$H14="Coaches","🌱 ",IF(Activities!$H14="Coordinators","⚙️ ",IF(Activities!$H14="Both","👥 ","")))&Activities!$B14&CHAR(10)&REPT("●",Activities!$F14),"") -> 👥 Administrator goal-setting, priorities & annual data review ●●
A15: =IF(Activities!$A15<>"",Activities!$A15,"") -> Pathway Strategy, Data & Certification | B15: =IF(Activities!$B15<>"",Activities!$B15,"") -> School goal progress checks and targeted support planning | C15: =IF(AND(Activities!$A15<>"",IF(Activities!$E15<>"",ISNUMBER(SEARCH(",1,",","&Activities!$E15&",")),AND(Activities!$C15<=1,Activities!$D15>=1))),IF(Activities!$H15="Coaches","🌱 ",IF(Activities!$H15="Coordinators","⚙️ ",IF(Activities!$H15="Both","👥 ","")))&Activities!$B15&CHAR(10)&REPT("●",Activities!$F15),"") | D15: =IF(AND(Activities!$A15<>"",IF(Activities!$E15<>"",ISNUMBER(SEARCH(",2,",","&Activities!$E15&",")),AND(Activities!$C15<=2,Activities!$D15>=2))),IF(Activities!$H15="Coaches","🌱 ",IF(Activities!$H15="Coordinators","⚙️ ",IF(Activities!$H15="Both","👥 ","")))&Activities!$B15&CHAR(10)&REPT("●",Activities!$F15),"") | E15: =IF(AND(Activities!$A15<>"",IF(Activities!$E15<>"",ISNUMBER(SEARCH(",3,",","&Activities!$E15&",")),AND(Activities!$C15<=3,Activities!$D15>=3))),IF(Activities!$H15="Coaches","🌱 ",IF(Activities!$H15="Coordinators","⚙️ ",IF(Activities!$H15="Both","👥 ","")))&Activities!$B15&CHAR(10)&REPT("●",Activities!$F15),"") | F15: =IF(AND(Activities!$A15<>"",IF(Activities!$E15<>"",ISNUMBER(SEARCH(",4,",","&Activities!$E15&",")),AND(Activities!$C15<=4,Activities!$D15>=4))),IF(Activities!$H15="Coaches","🌱 ",IF(Activities!$H15="Coordinators","⚙️ ",IF(Activities!$H15="Both","👥 ","")))&Activities!$B15&CHAR(10)&REPT("●",Activities!$F15),"") -> 👥 School goal progress checks and targeted support planning ●● | G15: =IF(AND(Activities!$A15<>"",IF(Activities!$E15<>"",ISNUMBER(SEARCH(",5,",","&Activities!$E15&",")),AND(Activities!$C15<=5,Activities!$D15>=5))),IF(Activities!$H15="Coaches","🌱 ",IF(Activities!$H15="Coordinators","⚙️ ",IF(Activities!$H15="Both","👥 ","")))&Activities!$B15&CHAR(10)&REPT("●",Activities!$F15),"") -> 👥 School goal progress checks and targeted support planning ●● | H15: =IF(AND(Activities!$A15<>"",IF(Activities!$E15<>"",ISNUMBER(SEARCH(",6,",","&Activities!$E15&",")),AND(Activities!$C15<=6,Activities!$D15>=6))),IF(Activities!$H15="Coaches","🌱 ",IF(Activities!$H15="Coordinators","⚙️ ",IF(Activities!$H15="Both","👥 ","")))&Activities!$B15&CHAR(10)&REPT("●",Activities!$F15),"") | I15: =IF(AND(Activities!$A15<>"",IF(Activities!$E15<>"",ISNUMBER(SEARCH(",7,",","&Activities!$E15&",")),AND(Activities!$C15<=7,Activities!$D15>=7))),IF(Activities!$H15="Coaches","🌱 ",IF(Activities!$H15="Coordinators","⚙️ ",IF(Activities!$H15="Both","👥 ","")))&Activities!$B15&CHAR(10)&REPT("●",Activities!$F15),"") | J15: =IF(AND(Activities!$A15<>"",IF(Activities!$E15<>"",ISNUMBER(SEARCH(",8,",","&Activities!$E15&",")),AND(Activities!$C15<=8,Activities!$D15>=8))),IF(Activities!$H15="Coaches","🌱 ",IF(Activities!$H15="Coordinators","⚙️ ",IF(Activities!$H15="Both","👥 ","")))&Activities!$B15&CHAR(10)&REPT("●",Activities!$F15),"") | K15: =IF(AND(Activities!$A15<>"",IF(Activities!$E15<>"",ISNUMBER(SEARCH(",9,",","&Activities!$E15&",")),AND(Activities!$C15<=9,Activities!$D15>=9))),IF(Activities!$H15="Coaches","🌱 ",IF(Activities!$H15="Coordinators","⚙️ ",IF(Activities!$H15="Both","👥 ","")))&Activities!$B15&CHAR(10)&REPT("●",Activities!$F15),"") | L15: =IF(AND(Activities!$A15<>"",IF(Activities!$E15<>"",ISNUMBER(SEARCH(",10,",","&Activities!$E15&",")),AND(Activities!$C15<=10,Activities!$D15>=10))),IF(Activities!$H15="Coaches","🌱 ",IF(Activities!$H15="Coordinators","⚙️ ",IF(Activities!$H15="Both","👥 ","")))&Activities!$B15&CHAR(10)&REPT("●",Activities!$F15),"") | M15: =IF(AND(Activities!$A15<>"",IF(Activities!$E15<>"",ISNUMBER(SEARCH(",11,",","&Activities!$E15&",")),AND(Activities!$C15<=11,Activities!$D15>=11))),IF(Activities!$H15="Coaches","🌱 ",IF(Activities!$H15="Coordinators","⚙️ ",IF(Activities!$H15="Both","👥 ","")))&Activities!$B15&CHAR(10)&REPT("●",Activities!$F15),"") -> 👥 School goal progress checks and targeted support planning ●● | N15: =IF(AND(Activities!$A15<>"",IF(Activities!$E15<>"",ISNUMBER(SEARCH(",12,",","&Activities!$E15&",")),AND(Activities!$C15<=12,Activities!$D15>=12))),IF(Activities!$H15="Coaches","🌱 ",IF(Activities!$H15="Coordinators","⚙️ ",IF(Activities!$H15="Both","👥 ","")))&Activities!$B15&CHAR(10)&REPT("●",Activities!$F15),"")
